Workbook
Name CapBase: Assumptions!$B$36
Name CapStress: Assumptions!$B$37
Name CapTarget: Assumptions!$B$35
Name Carry: Assumptions!$B$21
Name CatchUp: Assumptions!$B$23
Name ChecksStatus: Checks!$A$4
Name ClosingMonths: Assumptions!$B$8
Name Commitments: Assumptions!$B$5
Name CompanyCap: Assumptions!$B$10
Name CompanyCapPct: Assumptions!$B$9
Name CompanyMaxSPV: Assumptions!$B$11
Name EuropeMinPct: Assumptions!$B$12
Name FeeFirstClose: Assumptions!$B$18
Name FeeIP: Assumptions!$B$16
Name FeePost: Assumptions!$B$17
Name GPCommitMin: Assumptions!$B$25
Name GPCommitPct: Assumptions!$B$24
Name GrowthDirectMin: Assumptions!$D$48
Name Horizon: 'Cash flows'!$B$4
Name Hurdle: Assumptions!$B$22
Name IPYears: Assumptions!$B$7
Name QualifyingMinPct: Assumptions!$B$13
Name ResSeed_bridges: Assumptions!$B$55
Name ResSeed_graduation_pct: Assumptions!$B$52
Name ResSeed_next_round: Assumptions!$B$53
Name ResSeed_pro_rata_pct: Assumptions!$B$54
Name ResVenture_bridges: Assumptions!$C$55
Name ResVenture_graduation_pct: Assumptions!$C$52
Name ResVenture_next_round: Assumptions!$C$53
Name ResVenture_pro_rata_pct: Assumptions!$C$54
Name RunningCost: Assumptions!$B$20
Name SecCo1: Assumptions!$B$31
Name SecCo2: Assumptions!$B$32
Name SecPrice: Assumptions!$B$30
Name SecShare: Assumptions!$B$28
Name SecYear: Assumptions!$B$29
Name SetupCost: Assumptions!$B$19
Name TailCost: 'Cash flows'!$B$5
Name TermYears: Assumptions!$B$6

Sheet Read me
A1: ProFund Fund I — Fund model (v2)
A2: Model date 2026-10-29 · Seed to Growth · amounts in euros · contact alexandre@profund.vc
A4: PRE-MARKETING | B4: This document is a pre-marketing communication within the meaning of Article 4a of Regulation (EU) No 345/2013 (EuVECA). The fund is not yet established and no units may be subscribed at this stage. For professional and eligible investors only.
B5: All projections, targets, simulated portfolios, and return figures (IRR/DPI/MOIC) are indicative, hypothetical, and illustrative; actual results may differ materially.
B6: Fund expenses are an estimate pending the EuVECA manager's quote.
A8: Status | B8: =ChecksStatus -> ALL CHECKS PASS
A10: Tabs
A11: Assumptions | B11: Fund size, terms and fees, the partial secondary sale, the cap of each case, layer bounds and the follow-on reserve policy.
A12: Lines | B12: The simulation lines (Seed S-, Venture V-, Growth G-): entry, follow-on and exit inputs, then proceeds and MOIC per case, with layer subtotals.
A13: Construction | B13: Portfolio by layer, capital allocation, reserves vs policy, exposure per company and the fund returner.
A14: Cash flows | B14: Yearly flows per case: investments, exits incl. the year-6 secondary, fees, expenses, capital calls, the European waterfall step by step, LP and GP flows; net TVPI, IRR and DPI.
A15: Performance | B15: The Fund Performance table shown on profund.vc/pitch, linked to the tabs above.
A16: Checks | B16: Every output compared with the Python model the site and the fact sheet read (scripts/fund_model.py → src/data/fund.json). Change an input and they turn red: the workbook then shows your case, no longer the published one.
A18: Conventions
A19: Blue | B19: Input: change it and the whole workbook recalculates (Excel, LibreOffice, Google Sheets).
A20: Black | B20: Formula.
A21: Green | B21: Check against the Python model.
A22: Years | B22: Year 1 = year of the first closing; all flows at year end.
A23: Rounding | B23: Every amount is rounded to its display grain (EUR 10K below EUR 1M, EUR 100K above) before any sum, as in the Python model; ratios at their display precision.

Sheet Assumptions
A1: Assumptions
A2: Blue cells are inputs: change one and the whole workbook recalculates.
A4: Fund
A5: Commitments (target Fund I) | B5: 100000000
A6: Fund term (years) | B6: 10
A7: Investment period (years) | B7: 5 | F7: Management fee on commitments during this period
A8: Successive closings after the first (months) | B8: 24 | F8: Information; flows start at year 1 = year of first closing
A9: Max per company from the fund (% of commitments) | B9: 0.1
A10: Max per company from the fund | B10: =ROUND((CompanyCapPct*Commitments)/IF(ABS(CompanyCapPct*Commitments)<1000000,10000,100000),0)*IF(ABS(CompanyCapPct*Commitments)<1000000,10000,100000) -> 10000000
A11: Max per company with co-investment SPVs | B11: 15000000 | F11: Above the fund's cap: one or several SPVs offered to investors, outside the fund
A12: Europe (EU/EEA, UK, Switzerland), minimum | B12: 0.85 | F12: Information
A13: EuVECA qualifying investments, minimum | B13: 0.7 | F13: Information
A15: Terms
A16: Management fee during the investment period, on commitments | B16: 0.02
A17: Management fee after, on invested capital still held (at cost) | B17: 0.015
A18: Management fee, first-close investors | B18: 0.0175 | F18: Information only: the model keeps the standard fee (prudent)
A19: Set-up cost (year 1) | B19: 400000 | F19: Fund expenses are an estimate pending the EuVECA manager's quote.
A20: Running cost per year (platform, administration, audit) | B20: 350000 | F20: Fund expenses are an estimate pending the EuVECA manager's quote.
A21: Carried interest | B21: 0.2
A22: Hurdle (compounded annually) | B22: 0.08 | F22: European whole-of-fund waterfall
A23: GP catch-up | B23: 1
A24: GP commitment, minimum (% of commitments) | B24: 0.01 | F24: Information
A25: GP commitment, minimum | B25: =ROUND((GPCommitPct*Commitments)/IF(ABS(GPCommitPct*Commitments)<1000000,10000,100000),0)*IF(ABS(GPCommitPct*Commitments)<1000000,10000,100000) -> 1000000
A27: Early liquidity: partial secondary sale of the winners
A28: Share of the position sold | B28: 0.25
A29: Year of the secondary sale | B29: 6 | F29: Applies to every line of these companies that exits after this year
A30: Price, % of the exit value | B30: 0.6
A31: Company 1 sold in part | B31: S-01
A32: Company 2 sold in part | B32: V-01
A34: Cases: cap applied to every exit value, everything else unchanged
A35: Target case, exit value cap | B35: none | F35: Type an amount to cap, or 'none'
A36: Base case, exit value cap | B36: 500000000
A37: Stress case, exit value cap | B37: 250000000
A39: Layer bounds (portfolio construction rules)
B40: Seed | C40: Venture | D40: Growth
A41: Initial ticket, minimum | B41: 100000 | C41: 1500000 | D41: 5000000
A42: Initial ticket, maximum | B42: 1500000 | C42: 5000000 | D42: 10000000
A43: Entry post-money, minimum | B43: 5000000 | C43: 25000000 | D43: 80000000
A44: Entry post-money, maximum | B44: 20000000 | C44: 80000000 | D44: 400000000
A45: Entry stake, minimum | B45: 0.05 | C45: 0.05 | D45: 0.02
...

Sheet Lines
A1: Fund simulation — line by line
A2: Seed (S-), Venture (V-) and Growth (G-) lines. A line may group several companies (n): initial and follow-on are line totals. Blue = input, black = formula.
A4: INPUTS | P4: FORMULAS | Y4: CASH-FLOW HELPERS (used by the Cash flows tab)
A5: Deal ID | B5: Layer | C5: Company (exit key) | D5: Companies on the line | E5: Outcome | F5: Kind | G5: Initial tickets (line total) | H5: Entry post-money (per company) | I5: Follow-on (line total) | J5: Entry year | K5: Follow-on year | L5: Exit year | M5: Exit stake (diluted) | N5: Exit value (100%) | O5: Recovery multiple (if no exit value) | P5: Invested | Q5: Invested per company | R5: Entry stake | S5: Proceeds · Target | T5: Proceeds · Base | U5: Proceeds · Stress | V5: MOIC · Target | W5: MOIC · Base | X5: MOIC · Stress | Y5: Target · secondary sale proceeds | Z5: Target · proceeds at exit year | AA5: Target · cost sold in secondary | AB5: Target · cost at exit year | AC5: Base · secondary sale proceeds | AD5: Base · proceeds at exit year | AE5: Base · cost sold in secondary | AF5: Base · cost at exit year | AG5: Stress · secondary sale proceeds | AH5: Stress · proceeds at exit year | AI5: Stress · cost sold in secondary | AJ5: Stress · cost at exit year
A6: S-01 | B6: Seed | C6: S-01 | D6: 1 | E6: Fund returner | F6: new | G6: 1000000 | H6: 8000000 | I6: 2000000 | J6: 1 | K6: 2 | L6: 8 | M6: 0.045 | N6: 1500000000 | P6: =G6+I6 -> 3000000 | Q6: =P6/D6 -> 3000000 | R6: =ROUND(G6/D6/H6,3) -> 0.125 | S6: =IF(ISNUMBER($O6),ROUND(($O6*$P6)/IF(ABS($O6*$P6)<1000000,10000,100000),0)*IF(ABS($O6*$P6)<1000000,10000,100000),ROUND(($M6*IF(ISNUMBER(CapTarget),MIN($N6,CapTarget),$N6))/IF(ABS($M6*IF(ISNUMBER(CapTarget),MIN($N6,CapTarget),$N6))<1000000,10000,100000),0)*IF(ABS($M6*IF(ISNUMBER(CapTarget),MIN($N6,CapTarget),$N6))<1000000,10000,100000)) -> 67500000 | T6: =IF(ISNUMBER($O6),ROUND(($O6*$P6)/IF(ABS($O6*$P6)<1000000,10000,100000),0)*IF(ABS($O6*$P6)<1000000,10000,100000),ROUND(($M6*IF(ISNUMBER(CapBase),MIN($N6,CapBase),$N6))/IF(ABS($M6*IF(ISNUMBER(CapBase),MIN($N6,CapBase),$N6))<1000000,10000,100000),0)*IF(ABS($M6*IF(ISNUMBER(CapBase),MIN($N6,CapBase),$N6))<1000000,10000,100000)) -> 22500000 | U6: =IF(ISNUMBER($O6),ROUND(($O6*$P6)/IF(ABS($O6*$P6)<1000000,10000,100000),0)*IF(ABS($O6*$P6)<1000000,10000,100000),ROUND(($M6*IF(ISNUMBER(CapStress),MIN($N6,CapStress),$N6))/IF(ABS($M6*IF(ISNUMBER(CapStress),MIN($N6,CapStress),$N6))<1000000,10000,100000),0)*IF(ABS($M6*IF(ISNUMBER(CapStress),MIN($N6,CapStress),$N6))<1000000,10000,100000)) -> 11300000 | V6: =ROUND(S6/$P6,1) -> 22.5 | W6: =ROUND(T6/$P6,1) -> 7.5 | X6: =ROUND(U6/$P6,1) -> 3.8 | Y6: =IF(AND(OR($C6=SecCo1,$C6=SecCo2),$L6>SecYear,S6<>0),ROUND((SecShare*SecPrice*S6)/IF(ABS(SecShare*SecPrice*S6)<1000000,10000,100000),0)*IF(ABS(SecShare*SecPrice*S6)<1000000,10000,100000),0) -> 10100000 | Z6: =IF(AND(OR($C6=SecCo1,$C6=SecCo2),$L6>SecYear,S6<>0),ROUND(((1-SecShare)*S6)/IF(ABS((1-SecShare)*S6)<1000000,10000,100000),0)*IF(ABS((1-SecShare)*S6)<1000000,10000,100000),S6) -> 50600000 | AA6: =IF(AND(OR($C6=SecCo1,$C6=SecCo2),$L6>SecYear,S6<>0),SecShare*$P6,0) -> 750000 | AB6: =$P6-AA6 -> 2250000 | AC6: =IF(AND(OR($C6=SecCo1,$C6=SecCo2),$L6>SecYear,T6<>0),ROUND((SecShare*SecPrice*T6)/IF(ABS(SecShare*SecPrice*T6)<1000000,10000,100000),0)*IF(ABS(SecShare*SecPrice*T6)<1000000,10000,100000),0) -> 3400000 | AD6: =IF(AND(OR($C6=SecCo1,$C6=SecCo2),$L6>SecYear,T6<>0),ROUND(((1-SecShare)*T6)/IF(ABS((1-SecShare)*T6)<1000000,10000,100000),0)*IF(ABS((1-SecShare)*T6)<1000000,10000,100000),T6) -> 16900000 | AE6: =IF(AND(OR($C6=SecCo1,$C6=SecCo2),$L6>SecYear,T6<>0),SecShare*$P6,0) -> 750000 | AF6: =$P6-AE6 -> 2250000 | AG6: =IF(AND(OR($C6=SecCo1,$C6=SecCo2),$L6>SecYear,U6<>0),ROUND((SecShare*SecPrice*U6)/IF(ABS(SecShare*SecPrice*U6)<1000000,10000,100000),0)*IF(ABS(SecShare*SecPrice*U6)<1000000,10000,100000),0) -> 1700000 | AH6: =IF(AND(OR($C6=SecCo1,$C6=SecCo2),$L6>SecYear,U6<>0),ROUND(((1-SecShare)*U6)/IF(ABS((1-SecShare)*U6)<1000000,10000,100000),0)*IF(ABS((1-SecShare)*U6)<1000000,10000,100000),U6) -> 8500000 | AI6: =IF(AND(OR($C6=SecCo1,$C6=SecCo2),$L6>SecYear,U6<>0),SecShare*$P6,0) -> 750000 | AJ6: =$P6-AI6 -> 2250000
A7: S-02 | B7: Seed | C7: S-02 | D7: 1 | E7: Breakout | F7: new | G7: 750000 | H7: 8000000 | I7: 1500000 | J7: 1 | K7: 2 | L7: 7 | M7: 0.035 | N7: 600000000 | P7: =G7+I7 -> 2250000 | Q7: =P7/D7 -> 2250000 | R7: =ROUND(G7/D7/H7,3) -> 0.094 | S7: =IF(ISNUMBER($O7),ROUND(($O7*$P7)/IF(ABS($O7*$P7)<1000000,10000,100000),0)*IF(ABS($O7*$P7)<1000000,10000,100000),ROUND(($M7*IF(ISNUMBER(CapTarget),MIN($N7,CapTarget),$N7))/IF(ABS($M7*IF(ISNUMBER(CapTarget),MIN($N7,CapTarget),$N7))<1000000,10000,100000),0)*IF(ABS($M7*IF(ISNUMBER(CapTarget),MIN($N7,CapTarget),$N7))<1000000,10000,100000)) -> 21000000 | T7: =IF(ISNUMBER($O7),ROUND(($O7*$P7)/IF(ABS($O7*$P7)<1000000,10000,100000),0)*IF(ABS($O7*$P7)<1000000,10000,100000),ROUND(($M7*IF(ISNUMBER(CapBase),MIN($N7,CapBase),$N7))/IF(ABS($M7*IF(ISNUMBER(CapBase),MIN($N7,CapBase),$N7))<1000000,10000,100000),0)*IF(ABS($M7*IF(ISNUMBER(CapBase),MIN($N7,CapBase),$N7))<1000000,10000,100000)) -> 17500000 | U7: =IF(ISNUMBER($O7),ROUND(($O7*$P7)/IF(ABS($O7*$P7)<1000000,10000,100000),0)*IF(ABS($O7*$P7)<1000000,10000,100000),ROUND(($M7*IF(ISNUMBER(CapStress),MIN($N7,CapStress),$N7))/IF(ABS($M7*IF(ISNUMBER(CapStress),MIN($N7,CapStress),$N7))<1000000,10000,100000),0)*IF(ABS($M7*IF(ISNUMBER(CapStress),MIN($N7,CapStress),$N7))<1000000,10000,100000)) -> 8800000 | V7: =ROUND(S7/$P7,1) -> 9.3 | W7: =ROUND(T7/$P7,1) -> 7.8 | X7: =ROUND(U7/$P7,1) -> 3.9 | Y7: =IF(AND(OR($C7=SecCo1,$C7=SecCo2),$L7>SecYear,S7<>0),ROUND((SecShare*SecPrice*S7)/IF(ABS(SecShare*SecPrice*S7)<1000000,10000,100000),0)*IF(ABS(SecShare*SecPrice*S7)<1000000,10000,100000),0) -> 0 | Z7: =IF(AND(OR($C7=SecCo1,$C7=SecCo2),$L7>SecYear,S7<>0),ROUND(((1-SecShare)*S7)/IF(ABS((1-SecShare)*S7)<1000000,10000,100000),0)*IF(ABS((1-SecShare)*S7)<1000000,10000,100000),S7) -> 21000000 | AA7: =IF(AND(OR($C7=SecCo1,$C7=SecCo2),$L7>SecYear,S7<>0),SecShare*$P7,0) -> 0 | AB7: =$P7-AA7 -> 2250000 | AC7: =IF(AND(OR($C7=SecCo1,$C7=SecCo2),$L7>SecYear,T7<>0),ROUND((SecShare*SecPrice*T7)/IF(ABS(SecShare*SecPrice*T7)<1000000,10000,100000),0)*IF(ABS(SecShare*SecPrice*T7)<1000000,10000,100000),0) -> 0 | AD7: =IF(AND(OR($C7=SecCo1,$C7=SecCo2),$L7>SecYear,T7<>0),ROUND(((1-SecShare)*T7)/IF(ABS((1-SecShare)*T7)<1000000,10000,100000),0)*IF(ABS((1-SecShare)*T7)<1000000,10000,100000),T7) -> 17500000 | AE7: =IF(AND(OR($C7=SecCo1,$C7=SecCo2),$L7>SecYear,T7<>0),SecShare*$P7,0) -> 0 | AF7: =$P7-AE7 -> 2250000 | AG7: =IF(AND(OR($C7=SecCo1,$C7=SecCo2),$L7>SecYear,U7<>0),ROUND((SecShare*SecPrice*U7)/IF(ABS(SecShare*SecPrice*U7)<1000000,10000,100000),0)*IF(ABS(SecShare*SecPrice*U7)<1000000,10000,100000),0) -> 0 | AH7: =IF(AND(OR($C7=SecCo1,$C7=SecCo2),$L7>SecYear,U7<>0),ROUND(((1-SecShare)*U7)/IF(ABS((1-SecShare)*U7)<1000000,10000,100000),0)*IF(ABS((1-SecShare)*U7)<1000000,10000,100000),U7) -> 8800000 | AI7: =IF(AND(OR($C7=SecCo1,$C7=SecCo2),$L7>SecYear,U7<>0),SecShare*$P7,0) -> 0 | AJ7: =$P7-AI7 -> 2250000
A8: S-03 | B8: Seed | C8: S-03 | D8: 1 | E8: Breakout | F8: new | G8: 750000 | H8: 10000000 | I8: 1000000 | J8: 1 | K8: 3 | L8: 7 | M8: 0.03 | N8: 300000000 | P8: =G8+I8 -> 1750000 | Q8: =P8/D8 -> 1750000 | R8: =ROUND(G8/D8/H8,3) -> 0.075 | S8: =IF(ISNUMBER($O8),ROUND(($O8*$P8)/IF(ABS($O8*$P8)<1000000,10000,100000),0)*IF(ABS($O8*$P8)<1000000,10000,100000),ROUND(($M8*IF(ISNUMBER(CapTarget),MIN($N8,CapTarget),$N8))/IF(ABS($M8*IF(ISNUMBER(CapTarget),MIN($N8,CapTarget),$N8))<1000000,10000,100000),0)*IF(ABS($M8*IF(ISNUMBER(CapTarget),MIN($N8,CapTarget),$N8))<1000000,10000,100000)) -> 9000000 | T8: =IF(ISNUMBER($O8),ROUND(($O8*$P8)/IF(ABS($O8*$P8)<1000000,10000,100000),0)*IF(ABS($O8*$P8)<1000000,10000,100000),ROUND(($M8*IF(ISNUMBER(CapBase),MIN($N8,CapBase),$N8))/IF(ABS($M8*IF(ISNUMBER(CapBase),MIN($N8,CapBase),$N8))<1000000,10000,100000),0)*IF(ABS($M8*IF(ISNUMBER(CapBase),MIN($N8,CapBase),$N8))<1000000,10000,100000)) -> 9000000 | U8: =IF(ISNUMBER($O8),ROUND(($O8*$P8)/IF(ABS($O8*$P8)<1000000,10000,100000),0)*IF(ABS($O8*$P8)<1000000,10000,100000),ROUND(($M8*IF(ISNUMBER(CapStress),MIN($N8,CapStress),$N8))/IF(ABS($M8*IF(ISNUMBER(CapStress),MIN($N8,CapStress),$N8))<1000000,10000,100000),0)*IF(ABS($M8*IF(ISNUMBER(CapStress),MIN($N8,CapStress),$N8))<1000000,10000,100000)) -> 7500000 | V8: =ROUND(S8/$P8,1) -> 5.1 | W8: =ROUND(T8/$P8,1) -> 5.1 | X8: =ROUND(U8/$P8,1) -> 4.3 | Y8: =IF(AND(OR($C8=SecCo1,$C8=SecCo2),$L8>SecYear,S8<>0),ROUND((SecShare*SecPrice*S8)/IF(ABS(SecShare*SecPrice*S8)<1000000,10000,100000),0)*IF(ABS(SecShare*SecPrice*S8)<1000000,10000,100000),0) -> 0 | Z8: =IF(AND(OR($C8=SecCo1,$C8=SecCo2),$L8>SecYear,S8<>0),ROUND(((1-SecShare)*S8)/IF(ABS((1-SecShare)*S8)<1000000,10000,100000),0)*IF(ABS((1-SecShare)*S8)<1000000,10000,100000),S8) -> 9000000 | AA8: =IF(AND(OR($C8=SecCo1,$C8=SecCo2),$L8>SecYear,S8<>0),SecShare*$P8,0) -> 0 | AB8: =$P8-AA8 -> 1750000 | AC8: =IF(AND(OR($C8=SecCo1,$C8=SecCo2),$L8>SecYear,T8<>0),ROUND((SecShare*SecPrice*T8)/IF(ABS(SecShare*SecPrice*T8)<1000000,10000,100000),0)*IF(ABS(SecShare*SecPrice*T8)<1000000,10000,100000),0) -> 0 | AD8: =IF(AND(OR($C8=SecCo1,$C8=SecCo2),$L8>SecYear,T8<>0),ROUND(((1-SecShare)*T8)/IF(ABS((1-SecShare)*T8)<1000000,10000,100000),0)*IF(ABS((1-SecShare)*T8)<1000000,10000,100000),T8) -> 9000000 | AE8: =IF(AND(OR($C8=SecCo1,$C8=SecCo2),$L8>SecYear,T8<>0),SecShare*$P8,0) -> 0 | AF8: =$P8-AE8 -> 1750000 | AG8: =IF(AND(OR($C8=SecCo1,$C8=SecCo2),$L8>SecYear,U8<>0),ROUND((SecShare*SecPrice*U8)/IF(ABS(SecShare*SecPrice*U8)<1000000,10000,100000),0)*IF(ABS(SecShare*SecPrice*U8)<1000000,10000,100000),0) -> 0 | AH8: =IF(AND(OR($C8=SecCo1,$C8=SecCo2),$L8>SecYear,U8<>0),ROUND(((1-SecShare)*U8)/IF(ABS((1-SecShare)*U8)<1000000,10000,100000),0)*IF(ABS((1-SecShare)*U8)<1000000,10000,100000),U8) -> 7500000 | AI8: =IF(AND(OR($C8=SecCo1,$C8=SecCo2),$L8>SecYear,U8<>0),SecShare*$P8,0) -> 0 | AJ8: =$P8-AI8 -> 1750000
A9: S-04 | B9: Seed | C9: S-04 | D9: 1 | E9: Strategic exit | F9: new | G9: 500000 | H9: 8000000 | I9: 500000 | J9: 2 | K9: 3 | L9: 5 | M9: 0.05 | N9: 150000000 | P9: =G9+I9 -> 1000000 | Q9: =P9/D9 -> 1000000 | R9: =ROUND(G9/D9/H9,3) -> 0.063 | S9: =IF(ISNUMBER($O9),ROUND(($O9*$P9)/IF(ABS($O9*$P9)<1000000,10000,100000),0)*IF(ABS($O9*$P9)<1000000,10000,100000),ROUND(($M9*IF(ISNUMBER(CapTarget),MIN($N9,CapTarget),$N9))/IF(ABS($M9*IF(ISNUMBER(CapTarget),MIN($N9,CapTarget),$N9))<1000000,10000,100000),0)*IF(ABS($M9*IF(ISNUMBER(CapTarget),MIN($N9,CapTarget),$N9))<1000000,10000,100000)) -> 7500000 | T9: =IF(ISNUMBER($O9),ROUND(($O9*$P9)/IF(ABS($O9*$P9)<1000000,10000,100000),0)*IF(ABS($O9*$P9)<1000000,10000,100000),ROUND(($M9*IF(ISNUMBER(CapBase),MIN($N9,CapBase),$N9))/IF(ABS($M9*IF(ISNUMBER(CapBase),MIN($N9,CapBase),$N9))<1000000,10000,100000),0)*IF(ABS($M9*IF(ISNUMBER(CapBase),MIN($N9,CapBase),$N9))<1000000,10000,100000)) -> 7500000 | U9: =IF(ISNUMBER($O9),ROUND(($O9*$P9)/IF(ABS($O9*$P9)<1000000,10000,100000),0)*IF(ABS($O9*$P9)<1000000,10000,100000),ROUND(($M9*IF(ISNUMBER(CapStress),MIN($N9,CapStress),$N9))/IF(ABS($M9*IF(ISNUMBER(CapStress),MIN($N9,CapStress),$N9))<1000000,10000,100000),0)*IF(ABS($M9*IF(ISNUMBER(CapStress),MIN($N9,CapStress),$N9))<1000000,10000,100000)) -> 7500000 | V9: =ROUND(S9/$P9,1) -> 7.5 | W9: =ROUND(T9/$P9,1) -> 7.5 | X9: =ROUND(U9/$P9,1) -> 7.5 | Y9: =IF(AND(OR($C9=SecCo1,$C9=SecCo2),$L9>SecYear,S9<>0),ROUND((SecShare*SecPrice*S9)/IF(ABS(SecShare*SecPrice*S9)<1000000,10000,100000),0)*IF(ABS(SecShare*SecPrice*S9)<1000000,10000,100000),0) -> 0 | Z9: =IF(AND(OR($C9=SecCo1,$C9=SecCo2),$L9>SecYear,S9<>0),ROUND(((1-SecShare)*S9)/IF(ABS((1-SecShare)*S9)<1000000,10000,100000),0)*IF(ABS((1-SecShare)*S9)<1000000,10000,100000),S9) -> 7500000 | AA9: =IF(AND(OR($C9=SecCo1,$C9=SecCo2),$L9>SecYear,S9<>0),SecShare*$P9,0) -> 0 | AB9: =$P9-AA9 -> 1000000 | AC9: =IF(AND(OR($C9=SecCo1,$C9=SecCo2),$L9>SecYear,T9<>0),ROUND((SecShare*SecPrice*T9)/IF(ABS(SecShare*SecPrice*T9)<1000000,10000,100000),0)*IF(ABS(SecShare*SecPrice*T9)<1000000,10000,100000),0) -> 0 | AD9: =IF(AND(OR($C9=SecCo1,$C9=SecCo2),$L9>SecYear,T9<>0),ROUND(((1-SecShare)*T9)/IF(ABS((1-SecShare)*T9)<1000000,10000,100000),0)*IF(ABS((1-SecShare)*T9)<1000000,10000,100000),T9) -> 7500000 | AE9: =IF(AND(OR($C9=SecCo1,$C9=SecCo2),$L9>SecYear,T9<>0),SecShare*$P9,0) -> 0 | AF9: =$P9-AE9 -> 1000000 | AG9: =IF(AND(OR($C9=SecCo1,$C9=SecCo2),$L9>SecYear,U9<>0),ROUND((SecShare*SecPrice*U9)/IF(ABS(SecShare*SecPrice*U9)<1000000,10000,100000),0)*IF(ABS(SecShare*SecPrice*U9)<1000000,10000,100000),0) -> 0 | AH9: =IF(AND(OR($C9=SecCo1,$C9=SecCo2),$L9>SecYear,U9<>0),ROUND(((1-SecShare)*U9)/IF(ABS((1-SecShare)*U9)<1000000,10000,100000),0)*IF(ABS((1-SecShare)*U9)<1000000,10000,100000),U9) -> 7500000 | AI9: =IF(AND(OR($C9=SecCo1,$C9=SecCo2),$L9>SecYear,U9<>0),SecShare*$P9,0) -> 0 | AJ9: =$P9-AI9 -> 1000000
A10: S-05 | B10: Seed | C10: S-05 | D10: 1 | E10: Early exit (M&A) | F10: new | G10: 500000 | H10: 8000000 | I10: 500000 | J10: 1 | K10: 2 | L10: 4 | M10: 0.045 | N10: 60000000 | P10: =G10+I10 -> 1000000 | Q10: =P10/D10 -> 1000000 | R10: =ROUND(G10/D10/H10,3) -> 0.063 | S10: =IF(ISNUMBER($O10),ROUND(($O10*$P10)/IF(ABS($O10*$P10)<1000000,10000,100000),0)*IF(ABS($O10*$P10)<1000000,10000,100000),ROUND(($M10*IF(ISNUMBER(CapTarget),MIN($N10,CapTarget),$N10))/IF(ABS($M10*IF(ISNUMBER(CapTarget),MIN($N10,CapTarget),$N10))<1000000,10000,100000),0)*IF(ABS($M10*IF(ISNUMBER(CapTarget),MIN($N10,CapTarget),$N10))<1000000,10000,100000)) -> 2700000 | T10: =IF(ISNUMBER($O10),ROUND(($O10*$P10)/IF(ABS($O10*$P10)<1000000,10000,100000),0)*IF(ABS($O10*$P10)<1000000,10000,100000),ROUND(($M10*IF(ISNUMBER(CapBase),MIN($N10,CapBase),$N10))/IF(ABS($M10*IF(ISNUMBER(CapBase),MIN($N10,CapBase),$N10))<1000000,10000,100000),0)*IF(ABS($M10*IF(ISNUMBER(CapBase),MIN($N10,CapBase),$N10))<1000000,10000,100000)) -> 2700000 | U10: =IF(ISNUMBER($O10),ROUND(($O10*$P10)/IF(ABS($O10*$P10)<1000000,10000,100000),0)*IF(ABS($O10*$P10)<1000000,10000,100000),ROUND(($M10*IF(ISNUMBER(CapStress),MIN($N10,CapStress),$N10))/IF(ABS($M10*IF(ISNUMBER(CapStress),MIN($N10,CapStress),$N10))<1000000,10000,100000),0)*IF(ABS($M10*IF(ISNUMBER(CapStress),MIN($N10,CapStress),$N10))<1000000,10000,100000)) -> 2700000 | V10: =ROUND(S10/$P10,1) -> 2.7 | W10: =ROUND(T10/$P10,1) -> 2.7 | X10: =ROUND(U10/$P10,1) -> 2.7 | Y10: =IF(AND(OR($C10=SecCo1,$C10=SecCo2),$L10>SecYear,S10<>0),ROUND((SecShare*SecPrice*S10)/IF(ABS(SecShare*SecPrice*S10)<1000000,10000,100000),0)*IF(ABS(SecShare*SecPrice*S10)<1000000,10000,100000),0) -> 0 | Z10: =IF(AND(OR($C10=SecCo1,$C10=SecCo2),$L10>SecYear,S10<>0),ROUND(((1-SecShare)*S10)/IF(ABS((1-SecShare)*S10)<1000000,10000,100000),0)*IF(ABS((1-SecShare)*S10)<1000000,10000,100000),S10) -> 2700000 | AA10: =IF(AND(OR($C10=SecCo1,$C10=SecCo2),$L10>SecYear,S10<>0),SecShare*$P10,0) -> 0 | AB10: =$P10-AA10 -> 1000000 | AC10: =IF(AND(OR($C10=SecCo1,$C10=SecCo2),$L10>SecYear,T10<>0),ROUND((SecShare*SecPrice*T10)/IF(ABS(SecShare*SecPrice*T10)<1000000,10000,100000),0)*IF(ABS(SecShare*SecPrice*T10)<1000000,10000,100000),0) -> 0 | AD10: =IF(AND(OR($C10=SecCo1,$C10=SecCo2),$L10>SecYear,T10<>0),ROUND(((1-SecShare)*T10)/IF(ABS((1-SecShare)*T10)<1000000,10000,100000),0)*IF(ABS((1-SecShare)*T10)<1000000,10000,100000),T10) -> 2700000 | AE10: =IF(AND(OR($C10=SecCo1,$C10=SecCo2),$L10>SecYear,T10<>0),SecShare*$P10,0) -> 0 | AF10: =$P10-AE10 -> 1000000 | AG10: =IF(AND(OR($C10=SecCo1,$C10=SecCo2),$L10>SecYear,U10<>0),ROUND((SecShare*SecPrice*U10)/IF(ABS(SecShare*SecPrice*U10)<1000000,10000,100000),0)*IF(ABS(SecShare*SecPrice*U10)<1000000,10000,100000),0) -> 0 | AH10: =IF(AND(OR($C10=SecCo1,$C10=SecCo2),$L10>SecYear,U10<>0),ROUND(((1-SecShare)*U10)/IF(ABS((1-SecShare)*U10)<1000000,10000,100000),0)*IF(ABS((1-SecShare)*U10)<1000000,10000,100000),U10) -> 2700000 | AI10: =IF(AND(OR($C10=SecCo1,$C10=SecCo2),$L10>SecYear,U10<>0),SecShare*$P10,0) -> 0 | AJ10: =$P10-AI10 -> 1000000
A11: S-06 | B11: Seed | C11: S-06 | D11: 1 | E11: Early exit (M&A) | F11: new | G11: 300000 | H11: 6000000 | I11: 0 | J11: 2 | L11: 4 | M11: 0.04 | N11: 40000000 | P11: =G11+I11 -> 300000 | Q11: =P11/D11 -> 300000 | R11: =ROUND(G11/D11/H11,3) -> 0.05 | S11: =IF(ISNUMBER($O11),ROUND(($O11*$P11)/IF(ABS($O11*$P11)<1000000,10000,100000),0)*IF(ABS($O11*$P11)<1000000,10000,100000),ROUND(($M11*IF(ISNUMBER(CapTarget),MIN($N11,CapTarget),$N11))/IF(ABS($M11*IF(ISNUMBER(CapTarget),MIN($N11,CapTarget),$N11))<1000000,10000,100000),0)*IF(ABS($M11*IF(ISNUMBER(CapTarget),MIN($N11,CapTarget),$N11))<1000000,10000,100000)) -> 1600000 | T11: =IF(ISNUMBER($O11),ROUND(($O11*$P11)/IF(ABS($O11*$P11)<1000000,10000,100000),0)*IF(ABS($O11*$P11)<1000000,10000,100000),ROUND(($M11*IF(ISNUMBER(CapBase),MIN($N11,CapBase),$N11))/IF(ABS($M11*IF(ISNUMBER(CapBase),MIN($N11,CapBase),$N11))<1000000,10000,100000),0)*IF(ABS($M11*IF(ISNUMBER(CapBase),MIN($N11,CapBase),$N11))<1000000,10000,100000)) -> 1600000 | U11: =IF(ISNUMBER($O11),ROUND(($O11*$P11)/IF(ABS($O11*$P11)<1000000,10000,100000),0)*IF(ABS($O11*$P11)<1000000,10000,100000),ROUND(($M11*IF(ISNUMBER(CapStress),MIN($N11,CapStress),$N11))/IF(ABS($M11*IF(ISNUMBER(CapStress),MIN($N11,CapStress),$N11))<1000000,10000,100000),0)*IF(ABS($M11*IF(ISNUMBER(CapStress),MIN($N11,CapStress),$N11))<1000000,10000,100000)) -> 1600000 | V11: =ROUND(S11/$P11,1) -> 5.3 | W11: =ROUND(T11/$P11,1) -> 5.3 | X11: =ROUND(U11/$P11,1) -> 5.3 | Y11: =IF(AND(OR($C11=SecCo1,$C11=SecCo2),$L11>SecYear,S11<>0),ROUND((SecShare*SecPrice*S11)/IF(ABS(SecShare*SecPrice*S11)<1000000,10000,100000),0)*IF(ABS(SecShare*SecPrice*S11)<1000000,10000,100000),0) -> 0 | Z11: =IF(AND(OR($C11=SecCo1,$C11=SecCo2),$L11>SecYear,S11<>0),ROUND(((1-SecShare)*S11)/IF(ABS((1-SecShare)*S11)<1000000,10000,100000),0)*IF(ABS((1-SecShare)*S11)<1000000,10000,100000),S11) -> 1600000 | AA11: =IF(AND(OR($C11=SecCo1,$C11=SecCo2),$L11>SecYear,S11<>0),SecShare*$P11,0) -> 0 | AB11: =$P11-AA11 -> 300000 | AC11: =IF(AND(OR($C11=SecCo1,$C11=SecCo2),$L11>SecYear,T11<>0),ROUND((SecShare*SecPrice*T11)/IF(ABS(SecShare*SecPrice*T11)<1000000,10000,100000),0)*IF(ABS(SecShare*SecPrice*T11)<1000000,10000,100000),0) -> 0 | AD11: =IF(AND(OR($C11=SecCo1,$C11=SecCo2),$L11>SecYear,T11<>0),ROUND(((1-SecShare)*T11)/IF(ABS((1-SecShare)*T11)<1000000,10000,100000),0)*IF(ABS((1-SecShare)*T11)<1000000,10000,100000),T11) -> 1600000 | AE11: =IF(AND(OR($C11=SecCo1,$C11=SecCo2),$L11>SecYear,T11<>0),SecShare*$P11,0) -> 0 | AF11: =$P11-AE11 -> 300000 | AG11: =IF(AND(OR($C11=SecCo1,$C11=SecCo2),$L11>SecYear,U11<>0),ROUND((SecShare*SecPrice*U11)/IF(ABS(SecShare*SecPrice*U11)<1000000,10000,100000),0)*IF(ABS(SecShare*SecPrice*U11)<1000000,10000,100000),0) -> 0 | AH11: =IF(AND(OR($C11=SecCo1,$C11=SecCo2),$L11>SecYear,U11<>0),ROUND(((1-SecShare)*U11)/IF(ABS((1-SecShare)*U11)<1000000,10000,100000),0)*IF(ABS((1-SecShare)*U11)<1000000,10000,100000),U11) -> 1600000 | AI11: =IF(AND(OR($C11=SecCo1,$C11=SecCo2),$L11>SecYear,U11<>0),SecShare*$P11,0) -> 0 | AJ11: =$P11-AI11 -> 300000
A12: S-07–09 | B12: Seed | C12: S-07 | D12: 3 | E12: Zombies (×3) | F12: new | G12: 1200000 | H12: 8000000 | I12: 600000 | J12: 2 | K12: 3 | L12: 7 | O12: 0.5 | P12: =G12+I12 -> 1800000 | Q12: =P12/D12 -> 600000 | R12: =ROUND(G12/D12/H12,3) -> 0.05 | S12: =IF(ISNUMBER($O12),ROUND(($O12*$P12)/IF(ABS($O12*$P12)<1000000,10000,100000),0)*IF(ABS($O12*$P12)<1000000,10000,100000),ROUND(($M12*IF(ISNUMBER(CapTarget),MIN($N12,CapTarget),$N12))/IF(ABS($M12*IF(ISNUMBER(CapTarget),MIN($N12,CapTarget),$N12))<1000000,10000,100000),0)*IF(ABS($M12*IF(ISNUMBER(CapTarget),MIN($N12,CapTarget),$N12))<1000000,10000,100000)) -> 900000 | T12: =IF(ISNUMBER($O12),ROUND(($O12*$P12)/IF(ABS($O12*$P12)<1000000,10000,100000),0)*IF(ABS($O12*$P12)<1000000,10000,100000),ROUND(($M12*IF(ISNUMBER(CapBase),MIN($N12,CapBase),$N12))/IF(ABS($M12*IF(ISNUMBER(CapBase),MIN($N12,CapBase),$N12))<1000000,10000,100000),0)*IF(ABS($M12*IF(ISNUMBER(CapBase),MIN($N12,CapBase),$N12))<1000000,10000,100000)) -> 900000 | U12: =IF(ISNUMBER($O12),ROUND(($O12*$P12)/IF(ABS($O12*$P12)<1000000,10000,100000),0)*IF(ABS($O12*$P12)<1000000,10000,100000),ROUND(($M12*IF(ISNUMBER(CapStress),MIN($N12,CapStress),$N12))/IF(ABS($M12*IF(ISNUMBER(CapStress),MIN($N12,CapStress),$N12))<1000000,10000,100000),0)*IF(ABS($M12*IF(ISNUMBER(CapStress),MIN($N12,CapStress),$N12))<1000000,10000,100000)) -> 900000 | V12: =ROUND(S12/$P12,1) -> 0.5 | W12: =ROUND(T12/$P12,1) -> 0.5 | X12: =ROUND(U12/$P12,1) -> 0.5 | Y12: =IF(AND(OR($C12=SecCo1,$C12=SecCo2),$L12>SecYear,S12<>0),ROUND((SecShare*SecPrice*S12)/IF(ABS(SecShare*SecPrice*S12)<1000000,10000,100000),0)*IF(ABS(SecShare*SecPrice*S12)<1000000,10000,100000),0) -> 0 | Z12: =IF(AND(OR($C12=SecCo1,$C12=SecCo2),$L12>SecYear,S12<>0),ROUND(((1-SecShare)*S12)/IF(ABS((1-SecShare)*S12)<1000000,10000,100000),0)*IF(ABS((1-SecShare)*S12)<1000000,10000,100000),S12) -> 900000 | AA12: =IF(AND(OR($C12=SecCo1,$C12=SecCo2),$L12>SecYear,S12<>0),SecShare*$P12,0) -> 0 | AB12: =$P12-AA12 -> 1800000 | AC12: =IF(AND(OR($C12=SecCo1,$C12=SecCo2),$L12>SecYear,T12<>0),ROUND((SecShare*SecPrice*T12)/IF(ABS(SecShare*SecPrice*T12)<1000000,10000,100000),0)*IF(ABS(SecShare*SecPrice*T12)<1000000,10000,100000),0) -> 0 | AD12: =IF(AND(OR($C12=SecCo1,$C12=SecCo2),$L12>SecYear,T12<>0),ROUND(((1-SecShare)*T12)/IF(ABS((1-SecShare)*T12)<1000000,10000,100000),0)*IF(ABS((1-SecShare)*T12)<1000000,10000,100000),T12) -> 900000 | AE12: =IF(AND(OR($C12=SecCo1,$C12=SecCo2),$L12>SecYear,T12<>0),SecShare*$P12,0) -> 0 | AF12: =$P12-AE12 -> 1800000 | AG12: =IF(AND(OR($C12=SecCo1,$C12=SecCo2),$L12>SecYear,U12<>0),ROUND((SecShare*SecPrice*U12)/IF(ABS(SecShare*SecPrice*U12)<1000000,10000,100000),0)*IF(ABS(SecShare*SecPrice*U12)<1000000,10000,100000),0) -> 0 | AH12: =IF(AND(OR($C12=SecCo1,$C12=SecCo2),$L12>SecYear,U12<>0),ROUND(((1-SecShare)*U12)/IF(ABS((1-SecShare)*U12)<1000000,10000,100000),0)*IF(ABS((1-SecShare)*U12)<1000000,10000,100000),U12) -> 900000 | AI12: =IF(AND(OR($C12=SecCo1,$C12=SecCo2),$L12>SecYear,U12<>0),SecShare*$P12,0) -> 0 | AJ12: =$P12-AI12 -> 1800000
A13: S-10–18 | B13: Seed | C13: S-10 | D13: 9 | E13: Losses (×9) | F13: new | G13: 4000000 | H13: 8000000 | I13: 1400000 | J13: 2 | K13: 3 | L13: 5 | O13: 0 | P13: =G13+I13 -> 5400000 | Q13: =P13/D13 -> 600000 | R13: =ROUND(G13/D13/H13,3) -> 0.056 | S13: =IF(ISNUMBER($O13),ROUND(($O13*$P13)/IF(ABS($O13*$P13)<1000000,10000,100000),0)*IF(ABS($O13*$P13)<1000000,10000,100000),ROUND(($M13*IF(ISNUMBER(CapTarget),MIN($N13,CapTarget),$N13))/IF(ABS($M13*IF(ISNUMBER(CapTarget),MIN($N13,CapTarget),$N13))<1000000,10000,100000),0)*IF(ABS($M13*IF(ISNUMBER(CapTarget),MIN($N13,CapTarget),$N13))<1000000,10000,100000)) -> 0 | T13: =IF(ISNUMBER($O13),ROUND(($O13*$P13)/IF(ABS($O13*$P13)<1000000,10000,100000),0)*IF(ABS($O13*$P13)<1000000,10000,100000),ROUND(($M13*IF(ISNUMBER(CapBase),MIN($N13,CapBase),$N13))/IF(ABS($M13*IF(ISNUMBER(CapBase),MIN($N13,CapBase),$N13))<1000000,10000,100000),0)*IF(ABS($M13*IF(ISNUMBER(CapBase),MIN($N13,CapBase),$N13))<1000000,10000,100000)) -> 0 | U13: =IF(ISNUMBER($O13),ROUND(($O13*$P13)/IF(ABS($O13*$P13)<1000000,10000,100000),0)*IF(ABS($O13*$P13)<1000000,10000,100000),ROUND(($M13*IF(ISNUMBER(CapStress),MIN($N13,CapStress),$N13))/IF(ABS($M13*IF(ISNUMBER(CapStress),MIN($N13,CapStress),$N13))<1000000,10000,100000),0)*IF(ABS($M13*IF(ISNUMBER(CapStress),MIN($N13,CapStress),$N13))<1000000,10000,100000)) -> 0 | V13: =ROUND(S13/$P13,1) -> 0 | W13: =ROUND(T13/$P13,1) -> 0 | X13: =ROUND(U13/$P13,1) -> 0 | Y13: =IF(AND(OR($C13=SecCo1,$C13=SecCo2),$L13>SecYear,S13<>0),ROUND((SecShare*SecPrice*S13)/IF(ABS(SecShare*SecPrice*S13)<1000000,10000,100000),0)*IF(ABS(SecShare*SecPrice*S13)<1000000,10000,100000),0) -> 0 | Z13: =IF(AND(OR($C13=SecCo1,$C13=SecCo2),$L13>SecYear,S13<>0),ROUND(((1-SecShare)*S13)/IF(ABS((1-SecShare)*S13)<1000000,10000,100000),0)*IF(ABS((1-SecShare)*S13)<1000000,10000,100000),S13) -> 0 | AA13: =IF(AND(OR($C13=SecCo1,$C13=SecCo2),$L13>SecYear,S13<>0),SecShare*$P13,0) -> 0 | AB13: =$P13-AA13 -> 5400000 | AC13: =IF(AND(OR($C13=SecCo1,$C13=SecCo2),$L13>SecYear,T13<>0),ROUND((SecShare*SecPrice*T13)/IF(ABS(SecShare*SecPrice*T13)<1000000,10000,100000),0)*IF(ABS(SecShare*SecPrice*T13)<1000000,10000,100000),0) -> 0 | AD13: =IF(AND(OR($C13=SecCo1,$C13=SecCo2),$L13>SecYear,T13<>0),ROUND(((1-SecShare)*T13)/IF(ABS((1-SecShare)*T13)<1000000,10000,100000),0)*IF(ABS((1-SecShare)*T13)<1000000,10000,100000),T13) -> 0 | AE13: =IF(AND(OR($C13=SecCo1,$C13=SecCo2),$L13>SecYear,T13<>0),SecShare*$P13,0) -> 0 | AF13: =$P13-AE13 -> 5400000 | AG13: =IF(AND(OR($C13=SecCo1,$C13=SecCo2),$L13>SecYear,U13<>0),ROUND((SecShare*SecPrice*U13)/IF(ABS(SecShare*SecPrice*U13)<1000000,10000,100000),0)*IF(ABS(SecShare*SecPrice*U13)<1000000,10000,100000),0) -> 0 | AH13: =IF(AND(OR($C13=SecCo1,$C13=SecCo2),$L13>SecYear,U13<>0),ROUND(((1-SecShare)*U13)/IF(ABS((1-SecShare)*U13)<1000000,10000,100000),0)*IF(ABS((1-SecShare)*U13)<1000000,10000,100000),U13) -> 0 | AI13: =IF(AND(OR($C13=SecCo1,$C13=SecCo2),$L13>SecYear,U13<>0),SecShare*$P13,0) -> 0 | AJ13: =$P13-AI13 -> 5400000
A14: SUB | E14: (Seed) | G14: =SUM(G6:G13) -> 9000000 | I14: =SUM(I6:I13) -> 7500000 | P14: =SUM(P6:P13) -> 16500000 | S14: =SUM(S6:S13) -> 110200000 | T14: =SUM(T6:T13) -> 61700000 | U14: =SUM(U6:U13) -> 40300000 | V14: =ROUND(S14/P14,1) -> 6.7 | W14: =ROUND(T14/P14,1) -> 3.7 | X14: =ROUND(U14/P14,1) -> 2.4
A15: V-01 | B15: Venture | C15: V-01 | D15: 1 | E15: Anchor | F15: new | G15: 3000000 | H15: 45000000 | I15: 2000000 | J15: 1 | K15: 3 | L15: 8 | M15: 0.045 | N15: 1200000000 | P15: =G15+I15 -> 5000000 | Q15: =P15/D15 -> 5000000 | R15: =ROUND(G15/D15/H15,3) -> 0.067 | S15: =IF(ISNUMBER($O15),ROUND(($O15*$P15)/IF(ABS($O15*$P15)<1000000,10000,100000),0)*IF(ABS($O15*$P15)<1000000,10000,100000),ROUND(($M15*IF(ISNUMBER(CapTarget),MIN($N15,CapTarget),$N15))/IF(ABS($M15*IF(ISNUMBER(CapTarget),MIN($N15,CapTarget),$N15))<1000000,10000,100000),0)*IF(ABS($M15*IF(ISNUMBER(CapTarget),MIN($N15,CapTarget),$N15))<1000000,10000,100000)) -> 54000000 | T15: =IF(ISNUMBER($O15),ROUND(($O15*$P15)/IF(ABS($O15*$P15)<1000000,10000,100000),0)*IF(ABS($O15*$P15)<1000000,10000,100000),ROUND(($M15*IF(ISNUMBER(CapBase),MIN($N15,CapBase),$N15))/IF(ABS($M15*IF(ISNUMBER(CapBase),MIN($N15,CapBase),$N15))<1000000,10000,100000),0)*IF(ABS($M15*IF(ISNUMBER(CapBase),MIN($N15,CapBase),$N15))<1000000,10000,100000)) -> 22500000 | U15: =IF(ISNUMBER($O15),ROUND(($O15*$P15)/IF(ABS($O15*$P15)<1000000,10000,100000),0)*IF(ABS($O15*$P15)<1000000,10000,100000),ROUND(($M15*IF(ISNUMBER(CapStress),MIN($N15,CapStress),$N15))/IF(ABS($M15*IF(ISNUMBER(CapStress),MIN($N15,CapStress),$N15))<1000000,10000,100000),0)*IF(ABS($M15*IF(ISNUMBER(CapStress),MIN($N15,CapStress),$N15))<1000000,10000,100000)) -> 11300000 | V15: =ROUND(S15/$P15,1) -> 10.8 | W15: =ROUND(T15/$P15,1) -> 4.5 | X15: =ROUND(U15/$P15,1) -> 2.3 | Y15: =IF(AND(OR($C15=SecCo1,$C15=SecCo2),$L15>SecYear,S15<>0),ROUND((SecShare*SecPrice*S15)/IF(ABS(SecShare*SecPrice*S15)<1000000,10000,100000),0)*IF(ABS(SecShare*SecPrice*S15)<1000000,10000,100000),0) -> 8100000 | Z15: =IF(AND(OR($C15=SecCo1,$C15=SecCo2),$L15>SecYear,S15<>0),ROUND(((1-SecShare)*S15)/IF(ABS((1-SecShare)*S15)<1000000,10000,100000),0)*IF(ABS((1-SecShare)*S15)<1000000,10000,100000),S15) -> 40500000 | AA15: =IF(AND(OR($C15=SecCo1,$C15=SecCo2),$L15>SecYear,S15<>0),SecShare*$P15,0) -> 1250000 | AB15: =$P15-AA15 -> 3750000 | AC15: =IF(AND(OR($C15=SecCo1,$C15=SecCo2),$L15>SecYear,T15<>0),ROUND((SecShare*SecPrice*T15)/IF(ABS(SecShare*SecPrice*T15)<1000000,10000,100000),0)*IF(ABS(SecShare*SecPrice*T15)<1000000,10000,100000),0) -> 3400000 | AD15: =IF(AND(OR($C15=SecCo1,$C15=SecCo2),$L15>SecYear,T15<>0),ROUND(((1-SecShare)*T15)/IF(ABS((1-SecShare)*T15)<1000000,10000,100000),0)*IF(ABS((1-SecShare)*T15)<1000000,10000,100000),T15) -> 16900000 | AE15: =IF(AND(OR($C15=SecCo1,$C15=SecCo2),$L15>SecYear,T15<>0),SecShare*$P15,0) -> 1250000 | AF15: =$P15-AE15 -> 3750000 | AG15: =IF(AND(OR($C15=SecCo1,$C15=SecCo2),$L15>SecYear,U15<>0),ROUND((SecShare*SecPrice*U15)/IF(ABS(SecShare*SecPrice*U15)<1000000,10000,100000),0)*IF(ABS(SecShare*SecPrice*U15)<1000000,10000,100000),0) -> 1700000 | AH15: =IF(AND(OR($C15=SecCo1,$C15=SecCo2),$L15>SecYear,U15<>0),ROUND(((1-SecShare)*U15)/IF(ABS((1-SecShare)*U15)<1000000,10000,100000),0)*IF(ABS((1-SecShare)*U15)<1000000,10000,100000),U15) -> 8500000 | AI15: =IF(AND(OR($C15=SecCo1,$C15=SecCo2),$L15>SecYear,U15<>0),SecShare*$P15,0) -> 1250000 | AJ15: =$P15-AI15 -> 3750000
A16: V-02 | B16: Venture | C16: V-02 | D16: 1 | E16: Strategic win | F16: new | G16: 3000000 | H16: 45000000 | I16: 2000000 | J16: 1 | K16: 3 | L16: 7 | M16: 0.045 | N16: 600000000 | P16: =G16+I16 -> 5000000 | Q16: =P16/D16 -> 5000000 | R16: =ROUND(G16/D16/H16,3) -> 0.067 | S16: =IF(ISNUMBER($O16),ROUND(($O16*$P16)/IF(ABS($O16*$P16)<1000000,10000,100000),0)*IF(ABS($O16*$P16)<1000000,10000,100000),ROUND(($M16*IF(ISNUMBER(CapTarget),MIN($N16,CapTarget),$N16))/IF(ABS($M16*IF(ISNUMBER(CapTarget),MIN($N16,CapTarget),$N16))<1000000,10000,100000),0)*IF(ABS($M16*IF(ISNUMBER(CapTarget),MIN($N16,CapTarget),$N16))<1000000,10000,100000)) -> 27000000 | T16: =IF(ISNUMBER($O16),ROUND(($O16*$P16)/IF(ABS($O16*$P16)<1000000,10000,100000),0)*IF(ABS($O16*$P16)<1000000,10000,100000),ROUND(($M16*IF(ISNUMBER(CapBase),MIN($N16,CapBase),$N16))/IF(ABS($M16*IF(ISNUMBER(CapBase),MIN($N16,CapBase),$N16))<1000000,10000,100000),0)*IF(ABS($M16*IF(ISNUMBER(CapBase),MIN($N16,CapBase),$N16))<1000000,10000,100000)) -> 22500000 | U16: =IF(ISNUMBER($O16),ROUND(($O16*$P16)/IF(ABS($O16*$P16)<1000000,10000,100000),0)*IF(ABS($O16*$P16)<1000000,10000,100000),ROUND(($M16*IF(ISNUMBER(CapStress),MIN($N16,CapStress),$N16))/IF(ABS($M16*IF(ISNUMBER(CapStress),MIN($N16,CapStress),$N16))<1000000,10000,100000),0)*IF(ABS($M16*IF(ISNUMBER(CapStress),MIN($N16,CapStress),$N16))<1000000,10000,100000)) -> 11300000 | V16: =ROUND(S16/$P16,1) -> 5.4 | W16: =ROUND(T16/$P16,1) -> 4.5 | X16: =ROUND(U16/$P16,1) -> 2.3 | Y16: =IF(AND(OR($C16=SecCo1,$C16=SecCo2),$L16>SecYear,S16<>0),ROUND((SecShare*SecPrice*S16)/IF(ABS(SecShare*SecPrice*S16)<1000000,10000,100000),0)*IF(ABS(SecShare*SecPrice*S16)<1000000,10000,100000),0) -> 0 | Z16: =IF(AND(OR($C16=SecCo1,$C16=SecCo2),$L16>SecYear,S16<>0),ROUND(((1-SecShare)*S16)/IF(ABS((1-SecShare)*S16)<1000000,10000,100000),0)*IF(ABS((1-SecShare)*S16)<1000000,10000,100000),S16) -> 27000000 | AA16: =IF(AND(OR($C16=SecCo1,$C16=SecCo2),$L16>SecYear,S16<>0),SecShare*$P16,0) -> 0 | AB16: =$P16-AA16 -> 5000000 | AC16: =IF(AND(OR($C16=SecCo1,$C16=SecCo2),$L16>SecYear,T16<>0),ROUND((SecShare*SecPrice*T16)/IF(ABS(SecShare*SecPrice*T16)<1000000,10000,100000),0)*IF(ABS(SecShare*SecPrice*T16)<1000000,10000,100000),0) -> 0 | AD16: =IF(AND(OR($C16=SecCo1,$C16=SecCo2),$L16>SecYear,T16<>0),ROUND(((1-SecShare)*T16)/IF(ABS((1-SecShare)*T16)<1000000,10000,100000),0)*IF(ABS((1-SecShare)*T16)<1000000,10000,100000),T16) -> 22500000 | AE16: =IF(AND(OR($C16=SecCo1,$C16=SecCo2),$L16>SecYear,T16<>0),SecShare*$P16,0) -> 0 | AF16: =$P16-AE16 -> 5000000 | AG16: =IF(AND(OR($C16=SecCo1,$C16=SecCo2),$L16>SecYear,U16<>0),ROUND((SecShare*SecPrice*U16)/IF(ABS(SecShare*SecPrice*U16)<1000000,10000,100000),0)*IF(ABS(SecShare*SecPrice*U16)<1000000,10000,100000),0) -> 0 | AH16: =IF(AND(OR($C16=SecCo1,$C16=SecCo2),$L16>SecYear,U16<>0),ROUND(((1-SecShare)*U16)/IF(ABS((1-SecShare)*U16)<1000000,10000,100000),0)*IF(ABS((1-SecShare)*U16)<1000000,10000,100000),U16) -> 11300000 | AI16: =IF(AND(OR($C16=SecCo1,$C16=SecCo2),$L16>SecYear,U16<>0),SecShare*$P16,0) -> 0 | AJ16: =$P16-AI16 -> 5000000
A17: V-03 | B17: Venture | C17: V-03 | D17: 1 | E17: Strategic win | F17: new | G17: 3000000 | H17: 40000000 | I17: 1500000 | J17: 2 | K17: 4 | L17: 6 | M17: 0.045 | N17: 400000000 | P17: =G17+I17 -> 4500000 | Q17: =P17/D17 -> 4500000 | R17: =ROUND(G17/D17/H17,3) -> 0.075 | S17: =IF(ISNUMBER($O17),ROUND(($O17*$P17)/IF(ABS($O17*$P17)<1000000,10000,100000),0)*IF(ABS($O17*$P17)<1000000,10000,100000),ROUND(($M17*IF(ISNUMBER(CapTarget),MIN($N17,CapTarget),$N17))/IF(ABS($M17*IF(ISNUMBER(CapTarget),MIN($N17,CapTarget),$N17))<1000000,10000,100000),0)*IF(ABS($M17*IF(ISNUMBER(CapTarget),MIN($N17,CapTarget),$N17))<1000000,10000,100000)) -> 18000000 | T17: =IF(ISNUMBER($O17),ROUND(($O17*$P17)/IF(ABS($O17*$P17)<1000000,10000,100000),0)*IF(ABS($O17*$P17)<1000000,10000,100000),ROUND(($M17*IF(ISNUMBER(CapBase),MIN($N17,CapBase),$N17))/IF(ABS($M17*IF(ISNUMBER(CapBase),MIN($N17,CapBase),$N17))<1000000,10000,100000),0)*IF(ABS($M17*IF(ISNUMBER(CapBase),MIN($N17,CapBase),$N17))<1000000,10000,100000)) -> 18000000 | U17: =IF(ISNUMBER($O17),ROUND(($O17*$P17)/IF(ABS($O17*$P17)<1000000,10000,100000),0)*IF(ABS($O17*$P17)<1000000,10000,100000),ROUND(($M17*IF(ISNUMBER(CapStress),MIN($N17,CapStress),$N17))/IF(ABS($M17*IF(ISNUMBER(CapStress),MIN($N17,CapStress),$N17))<1000000,10000,100000),0)*IF(ABS($M17*IF(ISNUMBER(CapStress),MIN($N17,CapStress),$N17))<1000000,10000,100000)) -> 11300000 | V17: =ROUND(S17/$P17,1) -> 4 | W17: =ROUND(T17/$P17,1) -> 4 | X17: =ROUND(U17/$P17,1) -> 2.5 | Y17: =IF(AND(OR($C17=SecCo1,$C17=SecCo2),$L17>SecYear,S17<>0),ROUND((SecShare*SecPrice*S17)/IF(ABS(SecShare*SecPrice*S17)<1000000,10000,100000),0)*IF(ABS(SecShare*SecPrice*S17)<1000000,10000,100000),0) -> 0 | Z17: =IF(AND(OR($C17=SecCo1,$C17=SecCo2),$L17>SecYear,S17<>0),ROUND(((1-SecShare)*S17)/IF(ABS((1-SecShare)*S17)<1000000,10000,100000),0)*IF(ABS((1-SecShare)*S17)<1000000,10000,100000),S17) -> 18000000 | AA17: =IF(AND(OR($C17=SecCo1,$C17=SecCo2),$L17>SecYear,S17<>0),SecShare*$P17,0) -> 0 | AB17: =$P17-AA17 -> 4500000 | AC17: =IF(AND(OR($C17=SecCo1,$C17=SecCo2),$L17>SecYear,T17<>0),ROUND((SecShare*SecPrice*T17)/IF(ABS(SecShare*SecPrice*T17)<1000000,10000,100000),0)*IF(ABS(SecShare*SecPrice*T17)<1000000,10000,100000),0) -> 0 | AD17: =IF(AND(OR($C17=SecCo1,$C17=SecCo2),$L17>SecYear,T17<>0),ROUND(((1-SecShare)*T17)/IF(ABS((1-SecShare)*T17)<1000000,10000,100000),0)*IF(ABS((1-SecShare)*T17)<1000000,10000,100000),T17) -> 18000000 | AE17: =IF(AND(OR($C17=SecCo1,$C17=SecCo2),$L17>SecYear,T17<>0),SecShare*$P17,0) -> 0 | AF17: =$P17-AE17 -> 4500000 | AG17: =IF(AND(OR($C17=SecCo1,$C17=SecCo2),$L17>SecYear,U17<>0),ROUND((SecShare*SecPrice*U17)/IF(ABS(SecShare*SecPrice*U17)<1000000,10000,100000),0)*IF(ABS(SecShare*SecPrice*U17)<1000000,10000,100000),0) -> 0 | AH17: =IF(AND(OR($C17=SecCo1,$C17=SecCo2),$L17>SecYear,U17<>0),ROUND(((1-SecShare)*U17)/IF(ABS((1-SecShare)*U17)<1000000,10000,100000),0)*IF(ABS((1-SecShare)*U17)<1000000,10000,100000),U17) -> 11300000 | AI17: =IF(AND(OR($C17=SecCo1,$C17=SecCo2),$L17>SecYear,U17<>0),SecShare*$P17,0) -> 0 | AJ17: =$P17-AI17 -> 4500000
A18: V-04 | B18: Venture | C18: V-04 | D18: 1 | E18: Base hit | F18: new | G18: 3000000 | H18: 45000000 | I18: 1000000 | J18: 2 | K18: 4 | L18: 6 | M18: 0.04 | N18: 250000000 | P18: =G18+I18 -> 4000000 | Q18: =P18/D18 -> 4000000 | R18: =ROUND(G18/D18/H18,3) -> 0.067 | S18: =IF(ISNUMBER($O18),ROUND(($O18*$P18)/IF(ABS($O18*$P18)<1000000,10000,100000),0)*IF(ABS($O18*$P18)<1000000,10000,100000),ROUND(($M18*IF(ISNUMBER(CapTarget),MIN($N18,CapTarget),$N18))/IF(ABS($M18*IF(ISNUMBER(CapTarget),MIN($N18,CapTarget),$N18))<1000000,10000,100000),0)*IF(ABS($M18*IF(ISNUMBER(CapTarget),MIN($N18,CapTarget),$N18))<1000000,10000,100000)) -> 10000000 | T18: =IF(ISNUMBER($O18),ROUND(($O18*$P18)/IF(ABS($O18*$P18)<1000000,10000,100000),0)*IF(ABS($O18*$P18)<1000000,10000,100000),ROUND(($M18*IF(ISNUMBER(CapBase),MIN($N18,CapBase),$N18))/IF(ABS($M18*IF(ISNUMBER(CapBase),MIN($N18,CapBase),$N18))<1000000,10000,100000),0)*IF(ABS($M18*IF(ISNUMBER(CapBase),MIN($N18,CapBase),$N18))<1000000,10000,100000)) -> 10000000 | U18: =IF(ISNUMBER($O18),ROUND(($O18*$P18)/IF(ABS($O18*$P18)<1000000,10000,100000),0)*IF(ABS($O18*$P18)<1000000,10000,100000),ROUND(($M18*IF(ISNUMBER(CapStress),MIN($N18,CapStress),$N18))/IF(ABS($M18*IF(ISNUMBER(CapStress),MIN($N18,CapStress),$N18))<1000000,10000,100000),0)*IF(ABS($M18*IF(ISNUMBER(CapStress),MIN($N18,CapStress),$N18))<1000000,10000,100000)) -> 10000000 | V18: =ROUND(S18/$P18,1) -> 2.5 | W18: =ROUND(T18/$P18,1) -> 2.5 | X18: =ROUND(U18/$P18,1) -> 2.5 | Y18: =IF(AND(OR($C18=SecCo1,$C18=SecCo2),$L18>SecYear,S18<>0),ROUND((SecShare*SecPrice*S18)/IF(ABS(SecShare*SecPrice*S18)<1000000,10000,100000),0)*IF(ABS(SecShare*SecPrice*S18)<1000000,10000,100000),0) -> 0 | Z18: =IF(AND(OR($C18=SecCo1,$C18=SecCo2),$L18>SecYear,S18<>0),ROUND(((1-SecShare)*S18)/IF(ABS((1-SecShare)*S18)<1000000,10000,100000),0)*IF(ABS((1-SecShare)*S18)<1000000,10000,100000),S18) -> 10000000 | AA18: =IF(AND(OR($C18=SecCo1,$C18=SecCo2),$L18>SecYear,S18<>0),SecShare*$P18,0) -> 0 | AB18: =$P18-AA18 -> 4000000 | AC18: =IF(AND(OR($C18=SecCo1,$C18=SecCo2),$L18>SecYear,T18<>0),ROUND((SecShare*SecPrice*T18)/IF(ABS(SecShare*SecPrice*T18)<1000000,10000,100000),0)*IF(ABS(SecShare*SecPrice*T18)<1000000,10000,100000),0) -> 0 | AD18: =IF(AND(OR($C18=SecCo1,$C18=SecCo2),$L18>SecYear,T18<>0),ROUND(((1-SecShare)*T18)/IF(ABS((1-SecShare)*T18)<1000000,10000,100000),0)*IF(ABS((1-SecShare)*T18)<1000000,10000,100000),T18) -> 10000000 | AE18: =IF(AND(OR($C18=SecCo1,$C18=SecCo2),$L18>SecYear,T18<>0),SecShare*$P18,0) -> 0 | AF18: =$P18-AE18 -> 4000000 | AG18: =IF(AND(OR($C18=SecCo1,$C18=SecCo2),$L18>SecYear,U18<>0),ROUND((SecShare*SecPrice*U18)/IF(ABS(SecShare*SecPrice*U18)<1000000,10000,100000),0)*IF(ABS(SecShare*SecPrice*U18)<1000000,10000,100000),0) -> 0 | AH18: =IF(AND(OR($C18=SecCo1,$C18=SecCo2),$L18>SecYear,U18<>0),ROUND(((1-SecShare)*U18)/IF(ABS((1-SecShare)*U18)<1000000,10000,100000),0)*IF(ABS((1-SecShare)*U18)<1000000,10000,100000),U18) -> 10000000 | AI18: =IF(AND(OR($C18=SecCo1,$C18=SecCo2),$L18>SecYear,U18<>0),SecShare*$P18,0) -> 0 | AJ18: =$P18-AI18 -> 4000000
A19: V-05/06 | B19: Venture | C19: V-05 | D19: 2 | E19: Zombies (×2) | F19: new | G19: 6000000 | H19: 40000000 | I19: 1500000 | J19: 3 | K19: 4 | L19: 7 | O19: 0.4 | P19: =G19+I19 -> 7500000 | Q19: =P19/D19 -> 3750000 | R19: =ROUND(G19/D19/H19,3) -> 0.075 | S19: =IF(ISNUMBER($O19),ROUND(($O19*$P19)/IF(ABS($O19*$P19)<1000000,10000,100000),0)*IF(ABS($O19*$P19)<1000000,10000,100000),ROUND(($M19*IF(ISNUMBER(CapTarget),MIN($N19,CapTarget),$N19))/IF(ABS($M19*IF(ISNUMBER(CapTarget),MIN($N19,CapTarget),$N19))<1000000,10000,100000),0)*IF(ABS($M19*IF(ISNUMBER(CapTarget),MIN($N19,CapTarget),$N19))<1000000,10000,100000)) -> 3000000 | T19: =IF(ISNUMBER($O19),ROUND(($O19*$P19)/IF(ABS($O19*$P19)<1000000,10000,100000),0)*IF(ABS($O19*$P19)<1000000,10000,100000),ROUND(($M19*IF(ISNUMBER(CapBase),MIN($N19,CapBase),$N19))/IF(ABS($M19*IF(ISNUMBER(CapBase),MIN($N19,CapBase),$N19))<1000000,10000,100000),0)*IF(ABS($M19*IF(ISNUMBER(CapBase),MIN($N19,CapBase),$N19))<1000000,10000,100000)) -> 3000000 | U19: =IF(ISNUMBER($O19),ROUND(($O19*$P19)/IF(ABS($O19*$P19)<1000000,10000,100000),0)*IF(ABS($O19*$P19)<1000000,10000,100000),ROUND(($M19*IF(ISNUMBER(CapStress),MIN($N19,CapStress),$N19))/IF(ABS($M19*IF(ISNUMBER(CapStress),MIN($N19,CapStress),$N19))<1000000,10000,100000),0)*IF(ABS($M19*IF(ISNUMBER(CapStress),MIN($N19,CapStress),$N19))<1000000,10000,100000)) -> 3000000 | V19: =ROUND(S19/$P19,1) -> 0.4 | W19: =ROUND(T19/$P19,1) -> 0.4 | X19: =ROUND(U19/$P19,1) -> 0.4 | Y19: =IF(AND(OR($C19=SecCo1,$C19=SecCo2),$L19>SecYear,S19<>0),ROUND((SecShare*SecPrice*S19)/IF(ABS(SecShare*SecPrice*S19)<1000000,10000,100000),0)*IF(ABS(SecShare*SecPrice*S19)<1000000,10000,100000),0) -> 0 | Z19: =IF(AND(OR($C19=SecCo1,$C19=SecCo2),$L19>SecYear,S19<>0),ROUND(((1-SecShare)*S19)/IF(ABS((1-SecShare)*S19)<1000000,10000,100000),0)*IF(ABS((1-SecShare)*S19)<1000000,10000,100000),S19) -> 3000000 | AA19: =IF(AND(OR($C19=SecCo1,$C19=SecCo2),$L19>SecYear,S19<>0),SecShare*$P19,0) -> 0 | AB19: =$P19-AA19 -> 7500000 | AC19: =IF(AND(OR($C19=SecCo1,$C19=SecCo2),$L19>SecYear,T19<>0),ROUND((SecShare*SecPrice*T19)/IF(ABS(SecShare*SecPrice*T19)<1000000,10000,100000),0)*IF(ABS(SecShare*SecPrice*T19)<1000000,10000,100000),0) -> 0 | AD19: =IF(AND(OR($C19=SecCo1,$C19=SecCo2),$L19>SecYear,T19<>0),ROUND(((1-SecShare)*T19)/IF(ABS((1-SecShare)*T19)<1000000,10000,100000),0)*IF(ABS((1-SecShare)*T19)<1000000,10000,100000),T19) -> 3000000 | AE19: =IF(AND(OR($C19=SecCo1,$C19=SecCo2),$L19>SecYear,T19<>0),SecShare*$P19,0) -> 0 | AF19: =$P19-AE19 -> 7500000 | AG19: =IF(AND(OR($C19=SecCo1,$C19=SecCo2),$L19>SecYear,U19<>0),ROUND((SecShare*SecPrice*U19)/IF(ABS(SecShare*SecPrice*U19)<1000000,10000,100000),0)*IF(ABS(SecShare*SecPrice*U19)<1000000,10000,100000),0) -> 0 | AH19: =IF(AND(OR($C19=SecCo1,$C19=SecCo2),$L19>SecYear,U19<>0),ROUND(((1-SecShare)*U19)/IF(ABS((1-SecShare)*U19)<1000000,10000,100000),0)*IF(ABS((1-SecShare)*U19)<1000000,10000,100000),U19) -> 3000000 | AI19: =IF(AND(OR($C19=SecCo1,$C19=SecCo2),$L19>SecYear,U19<>0),SecShare*$P19,0) -> 0 | AJ19: =$P19-AI19 -> 7500000
A20: V-07/08 | B20: Venture | C20: V-07 | D20: 2 | E20: Losses (×2) | F20: new | G20: 6000000 | H20: 40000000 | I20: 2400000 | J20: 3 | K20: 4 | L20: 6 | O20: 0 | P20: =G20+I20 -> 8400000 | Q20: =P20/D20 -> 4200000 | R20: =ROUND(G20/D20/H20,3) -> 0.075 | S20: =IF(ISNUMBER($O20),ROUND(($O20*$P20)/IF(ABS($O20*$P20)<1000000,10000,100000),0)*IF(ABS($O20*$P20)<1000000,10000,100000),ROUND(($M20*IF(ISNUMBER(CapTarget),MIN($N20,CapTarget),$N20))/IF(ABS($M20*IF(ISNUMBER(CapTarget),MIN($N20,CapTarget),$N20))<1000000,10000,100000),0)*IF(ABS($M20*IF(ISNUMBER(CapTarget),MIN($N20,CapTarget),$N20))<1000000,10000,100000)) -> 0 | T20: =IF(ISNUMBER($O20),ROUND(($O20*$P20)/IF(ABS($O20*$P20)<1000000,10000,100000),0)*IF(ABS($O20*$P20)<1000000,10000,100000),ROUND(($M20*IF(ISNUMBER(CapBase),MIN($N20,CapBase),$N20))/IF(ABS($M20*IF(ISNUMBER(CapBase),MIN($N20,CapBase),$N20))<1000000,10000,100000),0)*IF(ABS($M20*IF(ISNUMBER(CapBase),MIN($N20,CapBase),$N20))<1000000,10000,100000)) -> 0 | U20: =IF(ISNUMBER($O20),ROUND(($O20*$P20)/IF(ABS($O20*$P20)<1000000,10000,100000),0)*IF(ABS($O20*$P20)<1000000,10000,100000),ROUND(($M20*IF(ISNUMBER(CapStress),MIN($N20,CapStress),$N20))/IF(ABS($M20*IF(ISNUMBER(CapStress),MIN($N20,CapStress),$N20))<1000000,10000,100000),0)*IF(ABS($M20*IF(ISNUMBER(CapStress),MIN($N20,CapStress),$N20))<1000000,10000,100000)) -> 0 | V20: =ROUND(S20/$P20,1) -> 0 | W20: =ROUND(T20/$P20,1) -> 0 | X20: =ROUND(U20/$P20,1) -> 0 | Y20: =IF(AND(OR($C20=SecCo1,$C20=SecCo2),$L20>SecYear,S20<>0),ROUND((SecShare*SecPrice*S20)/IF(ABS(SecShare*SecPrice*S20)<1000000,10000,100000),0)*IF(ABS(SecShare*SecPrice*S20)<1000000,10000,100000),0) -> 0 | Z20: =IF(AND(OR($C20=SecCo1,$C20=SecCo2),$L20>SecYear,S20<>0),ROUND(((1-SecShare)*S20)/IF(ABS((1-SecShare)*S20)<1000000,10000,100000),0)*IF(ABS((1-SecShare)*S20)<1000000,10000,100000),S20) -> 0 | AA20: =IF(AND(OR($C20=SecCo1,$C20=SecCo2),$L20>SecYear,S20<>0),SecShare*$P20,0) -> 0 | AB20: =$P20-AA20 -> 8400000 | AC20: =IF(AND(OR($C20=SecCo1,$C20=SecCo2),$L20>SecYear,T20<>0),ROUND((SecShare*SecPrice*T20)/IF(ABS(SecShare*SecPrice*T20)<1000000,10000,100000),0)*IF(ABS(SecShare*SecPrice*T20)<1000000,10000,100000),0) -> 0 | AD20: =IF(AND(OR($C20=SecCo1,$C20=SecCo2),$L20>SecYear,T20<>0),ROUND(((1-SecShare)*T20)/IF(ABS((1-SecShare)*T20)<1000000,10000,100000),0)*IF(ABS((1-SecShare)*T20)<1000000,10000,100000),T20) -> 0 | AE20: =IF(AND(OR($C20=SecCo1,$C20=SecCo2),$L20>SecYear,T20<>0),SecShare*$P20,0) -> 0 | AF20: =$P20-AE20 -> 8400000 | AG20: =IF(AND(OR($C20=SecCo1,$C20=SecCo2),$L20>SecYear,U20<>0),ROUND((SecShare*SecPrice*U20)/IF(ABS(SecShare*SecPrice*U20)<1000000,10000,100000),0)*IF(ABS(SecShare*SecPrice*U20)<1000000,10000,100000),0) -> 0 | AH20: =IF(AND(OR($C20=SecCo1,$C20=SecCo2),$L20>SecYear,U20<>0),ROUND(((1-SecShare)*U20)/IF(ABS((1-SecShare)*U20)<1000000,10000,100000),0)*IF(ABS((1-SecShare)*U20)<1000000,10000,100000),U20) -> 0 | AI20: =IF(AND(OR($C20=SecCo1,$C20=SecCo2),$L20>SecYear,U20<>0),SecShare*$P20,0) -> 0 | AJ20: =$P20-AI20 -> 8400000
A21: SUB | E21: (Venture) | G21: =SUM(G15:G20) -> 24000000 | I21: =SUM(I15:I20) -> 10400000 | P21: =SUM(P15:P20) -> 34400000 | S21: =SUM(S15:S20) -> 112000000 | T21: =SUM(T15:T20) -> 76000000 | U21: =SUM(U15:U20) -> 46900000 | V21: =ROUND(S21/P21,1) -> 3.3 | W21: =ROUND(T21/P21,1) -> 2.2 | X21: =ROUND(U21/P21,1) -> 1.4
A22: G-01 | B22: Growth | C22: S-01 | D22: 1 | E22: Breakout (S-01) | F22: follow_on | G22: 7000000 | H22: 250000000 | I22: 0 | J22: 3 | L22: 8 | M22: 0.022 | N22: 1500000000 | P22: =G22+I22 -> 7000000 | Q22: =P22/D22 -> 7000000 | R22: =ROUND(G22/D22/H22,3) -> 0.028 | S22: =IF(ISNUMBER($O22),ROUND(($O22*$P22)/IF(ABS($O22*$P22)<1000000,10000,100000),0)*IF(ABS($O22*$P22)<1000000,10000,100000),ROUND(($M22*IF(ISNUMBER(CapTarget),MIN($N22,CapTarget),$N22))/IF(ABS($M22*IF(ISNUMBER(CapTarget),MIN($N22,CapTarget),$N22))<1000000,10000,100000),0)*IF(ABS($M22*IF(ISNUMBER(CapTarget),MIN($N22,CapTarget),$N22))<1000000,10000,100000)) -> 33000000 | T22: =IF(ISNUMBER($O22),ROUND(($O22*$P22)/IF(ABS($O22*$P22)<1000000,10000,100000),0)*IF(ABS($O22*$P22)<1000000,10000,100000),ROUND(($M22*IF(ISNUMBER(CapBase),MIN($N22,CapBase),$N22))/IF(ABS($M22*IF(ISNUMBER(CapBase),MIN($N22,CapBase),$N22))<1000000,10000,100000),0)*IF(ABS($M22*IF(ISNUMBER(CapBase),MIN($N22,CapBase),$N22))<1000000,10000,100000)) -> 11000000 | U22: =IF(ISNUMBER($O22),ROUND(($O22*$P22)/IF(ABS($O22*$P22)<1000000,10000,100000),0)*IF(ABS($O22*$P22)<1000000,10000,100000),ROUND(($M22*IF(ISNUMBER(CapStress),MIN($N22,CapStress),$N22))/IF(ABS($M22*IF(ISNUMBER(CapStress),MIN($N22,CapStress),$N22))<1000000,10000,100000),0)*IF(ABS($M22*IF(ISNUMBER(CapStress),MIN($N22,CapStress),$N22))<1000000,10000,100000)) -> 5500000 | V22: =ROUND(S22/$P22,1) -> 4.7 | W22: =ROUND(T22/$P22,1) -> 1.6 | X22: =ROUND(U22/$P22,1) -> 0.8 | Y22: =IF(AND(OR($C22=SecCo1,$C22=SecCo2),$L22>SecYear,S22<>0),ROUND((SecShare*SecPrice*S22)/IF(ABS(SecShare*SecPrice*S22)<1000000,10000,100000),0)*IF(ABS(SecShare*SecPrice*S22)<1000000,10000,100000),0) -> 5000000 | Z22: =IF(AND(OR($C22=SecCo1,$C22=SecCo2),$L22>SecYear,S22<>0),ROUND(((1-SecShare)*S22)/IF(ABS((1-SecShare)*S22)<1000000,10000,100000),0)*IF(ABS((1-SecShare)*S22)<1000000,10000,100000),S22) -> 24800000 | AA22: =IF(AND(OR($C22=SecCo1,$C22=SecCo2),$L22>SecYear,S22<>0),SecShare*$P22,0) -> 1750000 | AB22: =$P22-AA22 -> 5250000 | AC22: =IF(AND(OR($C22=SecCo1,$C22=SecCo2),$L22>SecYear,T22<>0),ROUND((SecShare*SecPrice*T22)/IF(ABS(SecShare*SecPrice*T22)<1000000,10000,100000),0)*IF(ABS(SecShare*SecPrice*T22)<1000000,10000,100000),0) -> 1700000 | AD22: =IF(AND(OR($C22=SecCo1,$C22=SecCo2),$L22>SecYear,T22<>0),ROUND(((1-SecShare)*T22)/IF(ABS((1-SecShare)*T22)<1000000,10000,100000),0)*IF(ABS((1-SecShare)*T22)<1000000,10000,100000),T22) -> 8300000 | AE22: =IF(AND(OR($C22=SecCo1,$C22=SecCo2),$L22>SecYear,T22<>0),SecShare*$P22,0) -> 1750000 | AF22: =$P22-AE22 -> 5250000 | AG22: =IF(AND(OR($C22=SecCo1,$C22=SecCo2),$L22>SecYear,U22<>0),ROUND((SecShare*SecPrice*U22)/IF(ABS(SecShare*SecPrice*U22)<1000000,10000,100000),0)*IF(ABS(SecShare*SecPrice*U22)<1000000,10000,100000),0) -> 830000 | AH22: =IF(AND(OR($C22=SecCo1,$C22=SecCo2),$L22>SecYear,U22<>0),ROUND(((1-SecShare)*U22)/IF(ABS((1-SecShare)*U22)<1000000,10000,100000),0)*IF(ABS((1-SecShare)*U22)<1000000,10000,100000),U22) -> 4100000 | AI22: =IF(AND(OR($C22=SecCo1,$C22=SecCo2),$L22>SecYear,U22<>0),SecShare*$P22,0) -> 1750000 | AJ22: =$P22-AI22 -> 5250000
A23: G-02 | B23: Growth | C23: V-01 | D23: 1 | E23: Breakout (V-01) | F23: follow_on | G23: 5000000 | H23: 400000000 | I23: 0 | J23: 4 | L23: 8 | M23: 0.01 | N23: 1200000000 | P23: =G23+I23 -> 5000000 | Q23: =P23/D23 -> 5000000 | R23: =ROUND(G23/D23/H23,3) -> 0.013 | S23: =IF(ISNUMBER($O23),ROUND(($O23*$P23)/IF(ABS($O23*$P23)<1000000,10000,100000),0)*IF(ABS($O23*$P23)<1000000,10000,100000),ROUND(($M23*IF(ISNUMBER(CapTarget),MIN($N23,CapTarget),$N23))/IF(ABS($M23*IF(ISNUMBER(CapTarget),MIN($N23,CapTarget),$N23))<1000000,10000,100000),0)*IF(ABS($M23*IF(ISNUMBER(CapTarget),MIN($N23,CapTarget),$N23))<1000000,10000,100000)) -> 12000000 | T23: =IF(ISNUMBER($O23),ROUND(($O23*$P23)/IF(ABS($O23*$P23)<1000000,10000,100000),0)*IF(ABS($O23*$P23)<1000000,10000,100000),ROUND(($M23*IF(ISNUMBER(CapBase),MIN($N23,CapBase),$N23))/IF(ABS($M23*IF(ISNUMBER(CapBase),MIN($N23,CapBase),$N23))<1000000,10000,100000),0)*IF(ABS($M23*IF(ISNUMBER(CapBase),MIN($N23,CapBase),$N23))<1000000,10000,100000)) -> 5000000 | U23: =IF(ISNUMBER($O23),ROUND(($O23*$P23)/IF(ABS($O23*$P23)<1000000,10000,100000),0)*IF(ABS($O23*$P23)<1000000,10000,100000),ROUND(($M23*IF(ISNUMBER(CapStress),MIN($N23,CapStress),$N23))/IF(ABS($M23*IF(ISNUMBER(CapStress),MIN($N23,CapStress),$N23))<1000000,10000,100000),0)*IF(ABS($M23*IF(ISNUMBER(CapStress),MIN($N23,CapStress),$N23))<1000000,10000,100000)) -> 2500000 | V23: =ROUND(S23/$P23,1) -> 2.4 | W23: =ROUND(T23/$P23,1) -> 1 | X23: =ROUND(U23/$P23,1) -> 0.5 | Y23: =IF(AND(OR($C23=SecCo1,$C23=SecCo2),$L23>SecYear,S23<>0),ROUND((SecShare*SecPrice*S23)/IF(ABS(SecShare*SecPrice*S23)<1000000,10000,100000),0)*IF(ABS(SecShare*SecPrice*S23)<1000000,10000,100000),0) -> 1800000 | Z23: =IF(AND(OR($C23=SecCo1,$C23=SecCo2),$L23>SecYear,S23<>0),ROUND(((1-SecShare)*S23)/IF(ABS((1-SecShare)*S23)<1000000,10000,100000),0)*IF(ABS((1-SecShare)*S23)<1000000,10000,100000),S23) -> 9000000 | AA23: =IF(AND(OR($C23=SecCo1,$C23=SecCo2),$L23>SecYear,S23<>0),SecShare*$P23,0) -> 1250000 | AB23: =$P23-AA23 -> 3750000 | AC23: =IF(AND(OR($C23=SecCo1,$C23=SecCo2),$L23>SecYear,T23<>0),ROUND((SecShare*SecPrice*T23)/IF(ABS(SecShare*SecPrice*T23)<1000000,10000,100000),0)*IF(ABS(SecShare*SecPrice*T23)<1000000,10000,100000),0) -> 750000 | AD23: =IF(AND(OR($C23=SecCo1,$C23=SecCo2),$L23>SecYear,T23<>0),ROUND(((1-SecShare)*T23)/IF(ABS((1-SecShare)*T23)<1000000,10000,100000),0)*IF(ABS((1-SecShare)*T23)<1000000,10000,100000),T23) -> 3800000 | AE23: =IF(AND(OR($C23=SecCo1,$C23=SecCo2),$L23>SecYear,T23<>0),SecShare*$P23,0) -> 1250000 | AF23: =$P23-AE23 -> 3750000 | AG23: =IF(AND(OR($C23=SecCo1,$C23=SecCo2),$L23>SecYear,U23<>0),ROUND((SecShare*SecPrice*U23)/IF(ABS(SecShare*SecPrice*U23)<1000000,10000,100000),0)*IF(ABS(SecShare*SecPrice*U23)<1000000,10000,100000),0) -> 380000 | AH23: =IF(AND(OR($C23=SecCo1,$C23=SecCo2),$L23>SecYear,U23<>0),ROUND(((1-SecShare)*U23)/IF(ABS((1-SecShare)*U23)<1000000,10000,100000),0)*IF(ABS((1-SecShare)*U23)<1000000,10000,100000),U23) -> 1900000 | AI23: =IF(AND(OR($C23=SecCo1,$C23=SecCo2),$L23>SecYear,U23<>0),SecShare*$P23,0) -> 1250000 | AJ23: =$P23-AI23 -> 3750000
A24: G-03 | B24: Growth | C24: S-02 | D24: 1 | E24: Breakout (S-02) | F24: follow_on | G24: 5000000 | H24: 150000000 | I24: 0 | J24: 3 | L24: 7 | M24: 0.028 | N24: 600000000 | P24: =G24+I24 -> 5000000 | Q24: =P24/D24 -> 5000000 | R24: =ROUND(G24/D24/H24,3) -> 0.033 | S24: =IF(ISNUMBER($O24),ROUND(($O24*$P24)/IF(ABS($O24*$P24)<1000000,10000,100000),0)*IF(ABS($O24*$P24)<1000000,10000,100000),ROUND(($M24*IF(ISNUMBER(CapTarget),MIN($N24,CapTarget),$N24))/IF(ABS($M24*IF(ISNUMBER(CapTarget),MIN($N24,CapTarget),$N24))<1000000,10000,100000),0)*IF(ABS($M24*IF(ISNUMBER(CapTarget),MIN($N24,CapTarget),$N24))<1000000,10000,100000)) -> 16800000 | T24: =IF(ISNUMBER($O24),ROUND(($O24*$P24)/IF(ABS($O24*$P24)<1000000,10000,100000),0)*IF(ABS($O24*$P24)<1000000,10000,100000),ROUND(($M24*IF(ISNUMBER(CapBase),MIN($N24,CapBase),$N24))/IF(ABS($M24*IF(ISNUMBER(CapBase),MIN($N24,CapBase),$N24))<1000000,10000,100000),0)*IF(ABS($M24*IF(ISNUMBER(CapBase),MIN($N24,CapBase),$N24))<1000000,10000,100000)) -> 14000000 | U24: =IF(ISNUMBER($O24),ROUND(($O24*$P24)/IF(ABS($O24*$P24)<1000000,10000,100000),0)*IF(ABS($O24*$P24)<1000000,10000,100000),ROUND(($M24*IF(ISNUMBER(CapStress),MIN($N24,CapStress),$N24))/IF(ABS($M24*IF(ISNUMBER(CapStress),MIN($N24,CapStress),$N24))<1000000,10000,100000),0)*IF(ABS($M24*IF(ISNUMBER(CapStress),MIN($N24,CapStress),$N24))<1000000,10000,100000)) -> 7000000 | V24: =ROUND(S24/$P24,1) -> 3.4 | W24: =ROUND(T24/$P24,1) -> 2.8 | X24: =ROUND(U24/$P24,1) -> 1.4 | Y24: =IF(AND(OR($C24=SecCo1,$C24=SecCo2),$L24>SecYear,S24<>0),ROUND((SecShare*SecPrice*S24)/IF(ABS(SecShare*SecPrice*S24)<1000000,10000,100000),0)*IF(ABS(SecShare*SecPrice*S24)<1000000,10000,100000),0) -> 0 | Z24: =IF(AND(OR($C24=SecCo1,$C24=SecCo2),$L24>SecYear,S24<>0),ROUND(((1-SecShare)*S24)/IF(ABS((1-SecShare)*S24)<1000000,10000,100000),0)*IF(ABS((1-SecShare)*S24)<1000000,10000,100000),S24) -> 16800000 | AA24: =IF(AND(OR($C24=SecCo1,$C24=SecCo2),$L24>SecYear,S24<>0),SecShare*$P24,0) -> 0 | AB24: =$P24-AA24 -> 5000000 | AC24: =IF(AND(OR($C24=SecCo1,$C24=SecCo2),$L24>SecYear,T24<>0),ROUND((SecShare*SecPrice*T24)/IF(ABS(SecShare*SecPrice*T24)<1000000,10000,100000),0)*IF(ABS(SecShare*SecPrice*T24)<1000000,10000,100000),0) -> 0 | AD24: =IF(AND(OR($C24=SecCo1,$C24=SecCo2),$L24>SecYear,T24<>0),ROUND(((1-SecShare)*T24)/IF(ABS((1-SecShare)*T24)<1000000,10000,100000),0)*IF(ABS((1-SecShare)*T24)<1000000,10000,100000),T24) -> 14000000 | AE24: =IF(AND(OR($C24=SecCo1,$C24=SecCo2),$L24>SecYear,T24<>0),SecShare*$P24,0) -> 0 | AF24: =$P24-AE24 -> 5000000 | AG24: =IF(AND(OR($C24=SecCo1,$C24=SecCo2),$L24>SecYear,U24<>0),ROUND((SecShare*SecPrice*U24)/IF(ABS(SecShare*SecPrice*U24)<1000000,10000,100000),0)*IF(ABS(SecShare*SecPrice*U24)<1000000,10000,100000),0) -> 0 | AH24: =IF(AND(OR($C24=SecCo1,$C24=SecCo2),$L24>SecYear,U24<>0),ROUND(((1-SecShare)*U24)/IF(ABS((1-SecShare)*U24)<1000000,10000,100000),0)*IF(ABS((1-SecShare)*U24)<1000000,10000,100000),U24) -> 7000000 | AI24: =IF(AND(OR($C24=SecCo1,$C24=SecCo2),$L24>SecYear,U24<>0),SecShare*$P24,0) -> 0 | AJ24: =$P24-AI24 -> 5000000
